Workbook

Sheet PS SCript Builder
A1: Package Standard | B1: MPHAPPS | C1: Space | D1: =LEN(B13)-LEN(SUBSTITUTE(B13," ","")) -> 3 | G1: =TODAY() -> 44777 | I1: =NOW() -> 44777.025
A2: Publisher | B2: InH | C2: Install | D2: =LEN(B13)+8 -> 48 | E2: Package | G2: ='Referance - Row'!C2&B15&'Referance - Row'!D2&B16&'Referance - Row'!E2&B2&'Referance - Row'!F2&B6&'Referance - Row'!G2&B4&'Referance - Row'!H2&B7&'Referance - Row'!I2 -> New-CMPackage -Name "MPHAPPS InH CiscoAnyConectCleanup (V5.3)" -Description "MPHAPPS InH CiscoAnyConectCleanup (V5.3)" -Manufacturer "InH" -Language "" -Version "(V5.3)" -Path "\\172.16.100.56\Package_Source\Cleanup_Tools\CiscoAnyConnectCleanupToolV5.3\"
A3: Software name | B3: CiscoAnyConectCleanup | C3: Uninstall | D3: =LEN(B13)+10 -> 50
A4: Version | B4: (V5.3) | E4: Program to install | G4: ='Referance - Row'!C4&B15&'Referance - Row'!D4&B18&'Referance - Row'!E4&B19&'Referance - Row'!F4&B20&'Referance - Row'!G4&B21&'Referance - Row'!H4&B22&'Referance - Row'!I4&B23&'Referance - Row'!J4&B24&'Referance - Row'!K4&B25&'Referance - Row'!L4&B8&'Referance - Row'!M4 -> New-CMProgram -PackageName "MPHAPPS InH CiscoAnyConectCleanup (V5.3)" -StandardProgramName "MPHAPPS InH CiscoAnyConectCleanup (V5.3)-Install" -DiskSpaceRequirement 5 -DiskSpaceUnit GB -Duration 20 -RunType "Normal" -ProgramRunType "WhetherOrNotUserIsLoggedOn" -RunMode "RunWithAdministrativeRights" -UserInteraction 0 -CommandLine "CiscoAnyConnectCleanupToolV5.3.exe"
A5: Architecture | E5: Program to uninstall
A6: Language
A7: Path UNC | B7: \\172.16.100.56\Package_Source\Cleanup_Tools\CiscoAnyConnectCleanupToolV5.3\ | E7: Collection to install | G7: ='Referance - Row'!C8&B27&'Referance - Row'!D8&B28&'Referance - Row'!E8 -> New-CMDeviceCollection -Name "MPHAPPS InH CiscoAnyConectCleanup (V5.3)-install" -LimitingCollectionName "All Windows Workstation or Professional Systems"
A8: CommandLine to install | B8: CiscoAnyConnectCleanupToolV5.3.exe | E8: Collection to uninstall
A9: CommandLine to Uninstall
E10: DP Group
A11: CMD Split1 | B11: =IF(OR(LEN(B1)>=1,(LEN(B2)>=1)),B1&" ",B1)&IF(AND(LEN(B2)>=1,(LEN(B3)>=1)),B2&" ",B2)&IF(AND(LEN(B3)>=1,(LEN(B4)>=1)),B3&" ",B3) -> MPHAPPS InH CiscoAnyConectCleanup | E11: Mphasis & DR - Distribution Point of Application Pacakge Deployment | G11: ='Referance - Row'!$C$12&$B$15&'Referance - Row'!$D$12&E11&'Referance - Row'!$E$12 -> Start-CMContentDistribution -PackageName “MPHAPPS InH CiscoAnyConectCleanup (V5.3)” -DistributionPointGroupName "Mphasis & DR - Distribution Point of Application Pacakge Deployment"
A12: CMD Split2 | B12: =IF(AND(LEN(B4)>=1,(LEN(B5)>=1)),B4&" ",B4)&IF(AND(OR(LEN(B5)>=1,(LEN(B6)>=1)),(LEN(B6)>=1)),B5&" ",B5)&B6 -> (V5.3) | C12: PreviousCmd | D12: =IF(AND(LEN(B4)>=1,(LEN(B5)>=1)),B4&" ",B4)&IF(AND(LEN(B5)>=1,(LEN(B6)>=1)),B5&" ",B5)&B6 -> (V5.3) | E12: Mphasis & DR - Distribution Point of Application Pacakge Deployment
A13: Split Merge | B13: =B11&B12 -> MPHAPPS InH CiscoAnyConectCleanup (V5.3)
A15: CMPackage Name | B15: =B13 -> MPHAPPS InH CiscoAnyConectCleanup (V5.3) | E15: Deployment to install | G15: ='Referance - Row'!$C$14&$B$15&'Referance - Row'!$D$14&$B$18&'Referance - Row'!$E$14&$B$27&'Referance - Row'!$F$14&B30&'Referance - Row'!$G$14&$B$31&'Referance - Row'!$H$14&$B$32&'Referance - Row'!$I$14&$B$33&'Referance - Row'!$J$14&B34 -> New-CMPackageDeployment -StandardProgram –PackageName "MPHAPPS InH CiscoAnyConectCleanup (V5.3)" –StandardProgramName "MPHAPPS InH CiscoAnyConectCleanup (V5.3)-Install" –CollectionName "MPHAPPS InH CiscoAnyConectCleanup (V5.3)-Install" –ScheduleEvent AsSoonAsPossible –RerunBehavior RerunIfFailedPreviousAttempt –SystemRestart 0 –FastNetworkOption DownloadContentFromDistributionPointAndRunLocally –SlowNetworkOption DownloadContentFromDistributionPointAndLocally
A16: Description | B16: =B13 -> MPHAPPS InH CiscoAnyConectCleanup (V5.3) | E16: Deployment to Uninstall
A18: StandardProgramName | B18: =B15 -> MPHAPPS InH CiscoAnyConectCleanup (V5.3) | E18: Include Test Hosts to install | G18: ='Referance - Row'!C23&$B$27&'Referance - Row'!D23&'PS SCript Builder'!$B$36&'Referance - Row'!E23 -> Add-CMDeviceCollectionIncludeMembershipRule -CollectionName "MPHAPPS InH CiscoAnyConectCleanup (V5.3)-Install" -IncludeCollectionName "MPHAPPS Deployment Test Systems - All Locations"
A19: DiskSpaceRequirement | B19: 5
A20: DiskSpaceUnit | B20: GB
A21: Duration | B21: 20
A22: RunType | B22: Normal
A23: ProgramRunType | B23: WhetherOrNotUserIsLoggedOn
A24: RunMode | B24: RunWithAdministrativeRights
A25: UserInteraction | B25: 0
A27: Collection Name | B27: =B18 -> MPHAPPS InH CiscoAnyConectCleanup (V5.3)
A28: Limiting | B28: All Windows Workstation or Professional Systems
A30: ScheduleEvent | B30: AsSoonAsPossible
A31: RerunBehavior | B31: RerunIfFailedPreviousAttempt
A32: SystemRestart | B32: 0
A33: FastNetworkOption | B33: DownloadContentFromDistributionPointAndRunLocally
A34: SlowNetworkOption | B34: DownloadContentFromDistributionPointAndLocally
A36: Test Collection Name | B36: MPHAPPS Deployment Test Systems - All Locations
A37: All Systems | B37: All Windows Workstation or Professional Systems
E55: Site Wise
E56: CC4 | G56: ='Referance - Row'!$C$11&$B$15&'Referance - Row'!$D$11&'Referance - Column'!AI2&'Referance - Row'!$E$11 -> Start-CMContentDistribution -PackageName “MPHAPPS InH CiscoAnyConectCleanup (V5.3)” -DistributionPointName "SRVPUN02SSSVM01.CORP.MPHASIS.COM"
E57: ORR-IBCM | G57: ='Referance - Row'!$C$11&$B$15&'Referance - Row'!$D$11&'Referance - Column'!AI3&'Referance - Row'!$E$11 -> Start-CMContentDistribution -PackageName “MPHAPPS InH CiscoAnyConectCleanup (V5.3)” -DistributionPointName "SRVBAN19IBCMVM1.CORP.MPHASIS.COM"
E58: ORR-SITE | G58: ='Referance - Row'!$C$11&$B$15&'Referance - Row'!$D$11&'Referance - Column'!AI4&'Referance - Row'!$E$11 -> Start-CMContentDistribution -PackageName “MPHAPPS InH CiscoAnyConectCleanup (V5.3)” -DistributionPointName "SRVBAN19SMDPVM1.CORP.MPHASIS.COM"
E59: EON | G59: ='Referance - Row'!$C$11&$B$15&'Referance - Row'!$D$11&'Referance - Column'!AI5&'Referance - Row'!$E$11 -> Start-CMContentDistribution -PackageName “MPHAPPS InH CiscoAnyConectCleanup (V5.3)” -DistributionPointName "SRVPUN05SSSVM01.CORP.MPHASIS.COM"
E60: MUMBAI | G60: ='Referance - Row'!$C$11&$B$15&'Referance - Row'!$D$11&'Referance - Column'!AI6&'Referance - Row'!$E$11 -> Start-CMContentDistribution -PackageName “MPHAPPS InH CiscoAnyConectCleanup (V5.3)” -DistributionPointName "SRVMUM06SSSVM01.CORP.MPHASIS.COM"
E61: BAG | G61: ='Referance - Row'!$C$11&$B$15&'Referance - Row'!$D$11&'Referance - Column'!AI7&'Referance - Row'!$E$11 -> Start-CMContentDistribution -PackageName “MPHAPPS InH CiscoAnyConectCleanup (V5.3)” -DistributionPointName "SRVBAN09SSSVM01.CORP.MPHASIS.COM"
E62: KSHEMA | G62: ='Referance - Row'!$C$11&$B$15&'Referance - Row'!$D$11&'Referance - Column'!AI8&'Referance - Row'!$E$11 -> Start-CMContentDistribution -PackageName “MPHAPPS InH CiscoAnyConectCleanup (V5.3)” -DistributionPointName "SRVBAN04SSSVM01.CORP.MPHASIS.COM"
...

Sheet Package Information
B2: ="Package for "&'PS SCript Builder'!B2&" "&'PS SCript Builder'!B3&" "&'PS SCript Builder'!B4&" "&'PS SCript Builder'!B5&" "&'PS SCript Builder'!B6 -> Package for InH CiscoAnyConectCleanup (V5.3)
B3: Package Standard | C3: ='PS SCript Builder'!B1 -> MPHAPPS
B4: Publisher | C4: ='PS SCript Builder'!B2 -> InH
B5: Software name | C5: ='PS SCript Builder'!B3 -> CiscoAnyConectCleanup
B6: Version | C6: ='PS SCript Builder'!B4 -> (V5.3)
B7: Language | C7: ='PS SCript Builder'!B6 -> 0
B8: Architecture | C8: ='PS SCript Builder'!B5 -> 0
B9: Package Name | C9: ='PS SCript Builder'!B15 -> MPHAPPS InH CiscoAnyConectCleanup (V5.3)
B10: Collection Name 1 | C10: ='PS SCript Builder'!B27&"-Install" -> MPHAPPS InH CiscoAnyConectCleanup (V5.3)-Install
B11: Collection Name 2 | C11: ='PS SCript Builder'!B27&"-UnInstall" -> MPHAPPS InH CiscoAnyConectCleanup (V5.3)-UnInstall
B12: Collection Name 3 | C12: NA
B13: Deployment Name1 | C13: ='PS SCript Builder'!B15&"-Install" -> MPHAPPS InH CiscoAnyConectCleanup (V5.3)-Install
B14: Deployment Name2 | C14: ='PS SCript Builder'!B16&"-UnInstall" -> MPHAPPS InH CiscoAnyConectCleanup (V5.3)-UnInstall
B15: Deployment Name3 | C15: ='PS SCript Builder'!B17 -> 0
B16: Program Name 1 | C16: ='PS SCript Builder'!B18&"-Install" -> MPHAPPS InH CiscoAnyConectCleanup (V5.3)-Install
B17: Program Name 2 | C17: ='PS SCript Builder'!B18&"-UnInstall" -> MPHAPPS InH CiscoAnyConectCleanup (V5.3)-UnInstall
B18: Program Name 3 | C18: NA
B19: Package version | C19: ='PS SCript Builder'!B4 -> (V5.3)
B20: Installation time | C20: ="<"&'PS SCript Builder'!B21&"Minutes" -> <20Minutes
B21: Package size | C21: ="<"&'PS SCript Builder'!B19&'PS SCript Builder'!B20 -> <5GB
B22: Number of package | C22: 1
B23: Number of application | C23: 1
B24: Number of Program | C24: 1
B25: Restart | C25: Reboot not required
B26: user notification | C26: NO
B27: Comments | C27: Deployment

Sheet Package (Installation Only)
B2: ="Package for "&'PS SCript Builder'!B2&" "&'PS SCript Builder'!B3&" "&'PS SCript Builder'!B4&" "&'PS SCript Builder'!B5&" "&'PS SCript Builder'!B6 -> Package for InH CiscoAnyConectCleanup (V5.3)
B3: Package Standard | C3: ='PS SCript Builder'!B1 -> MPHAPPS
B4: Publisher | C4: ='PS SCript Builder'!B2 -> InH
B5: Software name | C5: ='PS SCript Builder'!B3 -> CiscoAnyConectCleanup
B6: Version | C6: ='PS SCript Builder'!B4 -> (V5.3)
B7: Language | C7: ='PS SCript Builder'!B6 -> 0
B8: Architecture | C8: ='PS SCript Builder'!B5 -> 0
B9: Package Name | C9: ='PS SCript Builder'!B15 -> MPHAPPS InH CiscoAnyConectCleanup (V5.3)
B10: Collection Name 1 | C10: ='PS SCript Builder'!B27&"-Install" -> MPHAPPS InH CiscoAnyConectCleanup (V5.3)-Install
B11: Deployment Name1 | C11: ='PS SCript Builder'!B15&"-Install" -> MPHAPPS InH CiscoAnyConectCleanup (V5.3)-Install
B12: Program Name 1 | C12: ='PS SCript Builder'!B18&"-Install" -> MPHAPPS InH CiscoAnyConectCleanup (V5.3)-Install
B13: Package version | C13: ='PS SCript Builder'!B4 -> (V5.3)
B14: Installation time | C14: ="<"&'PS SCript Builder'!B21&"Minutes" -> <20Minutes
B15: Package size | C15: ="<"&'PS SCript Builder'!B19&'PS SCript Builder'!B20 -> <5GB
B16: Number of package | C16: 1
B17: Number of application | C17: 1
B18: Number of Program | C18: 1
B19: Restart | C19: Reboot not required
B20: user notification | C20: NO
B21: Comments | C21: Deployment

Sheet Referance - Column
A1: Sl | B1: Location | C1: Distribution Point | E1: Sl | F1: DiskSpaceRequirement | H1: DiskSpaceUnit | J1: Sl | K1: Duration | M1: RunType | O1: ProgramRunType | Q1: RunMode | S1: UserInteraction | U1: Architecture | W1: Schedule Event | Y1: RerunBehavior | AA1: System Reboot | AC1: FastNetworkOption | AE1: SlowNetworkOption | AG1: Sl | AH1: Location | AI1: DP Name
A2: 1 | B2: CC4 | C2: SRVPUN02SSSVM01.CORP.MPHASIS.COM | E2: 1 | F2: 1 | H2: GB | J2: 1 | K2: 20 | M2: Normal | O2: WhetherOrNotUserIsLoggedOn | Q2: RunWithAdministrativeRights | S2: 0 | U2: (x86) | W2: AsSoonAsPossible | Y2: RerunIfFailedPreviousAttempt | AA2: 0 | AC2: DownloadContentFromDistributionPointAndRunLocally | AE2: DoNotRunProgram | AG2: 1 | AH2: CC4 | AI2: SRVPUN02SSSVM01.CORP.MPHASIS.COM
A3: 2 | B3: ORR-IBCM | C3: SRVBAN19IBCMVM1.CORP.MPHASIS.COM | E3: 2 | F3: 2 | H3: MB | J3: 2 | K3: 25 | M3: Hidden | O3: OnlyWhenNoUserIsLoggedOn | Q3: RunWithUserRights | S3: 1 | U3: (x64) | W3: LogOff | Y3: RerunIfSucceededOnPreviousAttempt | AA3: 1 | AC3: RunProgramFromDistributionPoint | AE3: DownloadContentFromDistributionPointAndLocally | AG3: 2 | AH3: ORR-IBCM | AI3: SRVBAN19IBCMVM1.CORP.MPHASIS.COM
A4: 3 | B4: ORR-SITE | C4: SRVBAN19SMDPVM1.CORP.MPHASIS.COM | E4: 3 | F4: 3 | H4: KB | J4: 3 | K4: 30 | M4: Maximized | O4: OnlyWhenUserIsLoggedOn | U4: (x86 x64) | W4: LogOn | Y4: AlwaysRerunProgram | AE4: RunProgramFromDistributionPoint | AG4: 3 | AH4: ORR-SITE | AI4: SRVBAN19SMDPVM1.CORP.MPHASIS.COM
A5: 4 | B5: EON | C5: SRVPUN05SSSVM01.CORP.MPHASIS.COM | E5: 4 | F5: 4 | J5: 4 | K5: 35 | M5: Minimized | O5: WhetherOrNotUserIsLoggedOn | Y5: NeverRerunDeployedProgram | AG5: 4 | AH5: EON | AI5: SRVPUN05SSSVM01.CORP.MPHASIS.COM
A6: 5 | B6: MUMBAI | C6: SRVMUM06SSSVM01.CORP.MPHASIS.COM | E6: 5 | F6: 5 | J6: 5 | K6: 40 | AG6: 5 | AH6: MUMBAI | AI6: SRVMUM06SSSVM01.CORP.MPHASIS.COM
A7: 6 | B7: BAG | C7: SRVBAN09SSSVM01.CORP.MPHASIS.COM | E7: 6 | F7: 6 | J7: 6 | K7: 45 | AG7: 6 | AH7: BAG | AI7: SRVBAN09SSSVM01.CORP.MPHASIS.COM
A8: 7 | B8: KSHEMA | C8: SRVBAN04SSSVM01.CORP.MPHASIS.COM | E8: 7 | F8: 7 | J8: 7 | K8: 50 | AG8: 7 | AH8: KSHEMA | AI8: SRVBAN04SSSVM01.CORP.MPHASIS.COM
A9: 8 | B9: MLR | C9: SRVMAN01SSSVM01.CORP.MPHASIS.COM | E9: 8 | F9: 8 | J9: 8 | K9: 55 | AG9: 8 | AH9: MLR | AI9: SRVMAN01SSSVM01.CORP.MPHASIS.COM
A10: 9 | B10: CHE | C10: SRVCHE03SSSVM01.CORP.MPHASIS.COM | E10: 9 | F10: 9 | J10: 9 | K10: 60 | AG10: 9 | AH10: CHE | AI10: SRVCHE03SSSVM01.CORP.MPHASIS.COM
A11: 10 | B11: M90 | C11: SRVBAN24SSSVM01.CORP.MPHASIS.COM | E11: 10 | F11: 10 | J11: 10 | K11: 65 | AG11: 10 | AH11: M90 | AI11: SRVBAN24SSSVM01.CORP.MPHASIS.COM
A12: 11 | B12: POLAND | C12: SRVPOL01SSSVM01.CORP.MPHASIS.COM | J12: 11 | K12: 70 | AG12: 11 | AH12: POLAND | AI12: SRVPOL01SSSVM01.CORP.MPHASIS.COM
A13: 12 | B13: HYD | C13: SRVHYD03SCCMPH1.CORP.MPHASIS.COM | J13: 12 | K13: 75 | AG13: 12 | AH13: HYD | AI13: SRVHYD03SCCMPH1.CORP.MPHASIS.COM
J14: 13 | K14: 80
A15: Sl | B15: Group | C15: Distribution PointGroup | J15: 14 | K15: 85
A16: 1 | C16: DR - Distribution Point for Application Package Deployment | J16: 15 | K16: 90
A17: 2 | C17: DR - Distribution Point for OSD | J17: 16 | K17: 95
A18: 3 | C18: Mphasis - Distribution Point for Application Package Deployment | J18: 17 | K18: 100
A19: 4 | C19: Mphasis - Distribution Point for OSD | J19: 18 | K19: 105
A20: 5 | C20: Mphasis & DR - Distribution Point for OSD | J20: 19 | K20: 110
A21: 6 | C21: Mphasis & DR - Distribution Point of Application Pacakge Deployment | J21: 20 | K21: 115
A22: 7 | C22: Server Management Distribution Group | J22: 21 | K22: 120

Sheet Referance - Row
A2: Package | C2: New-CMPackage -Name " | D2: " -Description " | E2: " -Manufacturer " | F2: " -Language " | G2: " -Version " | H2: " -Path " | I2: "
A4: Program to Install | C4: New-CMProgram -PackageName " | D4: " -StandardProgramName " | E4: -Install" -DiskSpaceRequirement | F4: -DiskSpaceUnit | G4: -Duration | H4: -RunType " | I4: " -ProgramRunType " | J4: " -RunMode " | K4: " -UserInteraction | L4: -CommandLine " | M4: "
A5: Program to UnInstall | C5: New-CMProgram -PackageName " | D5: " -StandardProgramName " | E5: -Uninstall" -DiskSpaceRequirement | F5: -DiskSpaceUnit | G5: -Duration | H5: -RunType " | I5: " -ProgramRunType " | J5: " -RunMode " | K5: " -UserInteraction | L5: -CommandLine " | M5: "
A6: Program to Re-Install | C6: New-CMProgram -PackageName " | D6: " -StandardProgramName " | E6: -RE-Install" -DiskSpaceRequirement | F6: -DiskSpaceUnit | G6: -Duration | H6: -RunType " | I6: " -ProgramRunType " | J6: " -RunMode " | K6: " -UserInteraction | L6: -CommandLine " | M6: "
A8: Collection to install | C8: New-CMDeviceCollection -Name " | D8: -install" -LimitingCollectionName " | E8: "
A9: Collection to Unnstall | C9: New-CMDeviceCollection -Name " | D9: -Uninstall" -LimitingCollectionName " | E9: "
A11: Dist Points | C11: Start-CMContentDistribution -PackageName “ | D11: ” -DistributionPointName " | E11: "
A12: Dist Points | C12: Start-CMContentDistribution -PackageName “ | D12: ” -DistributionPointGroupName " | E12: "
A14: Deployment to install | C14: New-CMPackageDeployment -StandardProgram –PackageName " | D14: " –StandardProgramName " | E14: -Install" –CollectionName " | F14: -Install" –ScheduleEvent | G14: –RerunBehavior | H14: –SystemRestart | I14: –FastNetworkOption | J14: –SlowNetworkOption
A15: Deployment to Uninstall | C15: New-CMPackageDeployment -StandardProgram –PackageName " | D15: " –StandardProgramName " | E15: -UnInstall" –CollectionName " | F15: -UnInstall" –ScheduleEvent | G15: –RerunBehavior | H15: –SystemRestart | I15: –FastNetworkOption | J15: –SlowNetworkOption
A18: Delete Package | C18: Remove-CMPackage -Name " | D18: " -force
A20: Collection Delete Install | C20: Remove-CMDeviceCollection -Name " | D20: -Install" -force
A21: Collection Delete Uninstall | C21: Remove-CMDeviceCollection -Name " | D21: -UnInstall" -force
A23: Include Test Hosts to install | C23: Add-CMDeviceCollectionIncludeMembershipRule -CollectionName " | D23: -Install" -IncludeCollectionName " | E23: "
A24: Include Test Hosts to Uninstall | C24: Add-CMDeviceCollectionIncludeMembershipRule -CollectionName " | D24: -Uninstall" -IncludeCollectionName " | E24: "
A26: Exclude Test Hosts from Install | C26: Remove-CMDeviceCollectionIncludeMembershipRule -CollectionName " | D26: -install" -IncludeCollectionName " | E26: " -force
A27: Exclude Test Hosts from UInstall | C27: Remove-CMDeviceCollectionIncludeMembershipRule -CollectionName " | D27: -Uninstall" -IncludeCollectionName " | E27: " -force
A29: Include All Hosts to install | C29: Add-CMDeviceCollectionIncludeMembershipRule -CollectionName " | D29: -install" -IncludeCollectionName " | E29: "
A30: Include All Hosts to Uninstall | C30: Add-CMDeviceCollectionIncludeMembershipRule -CollectionName " | D30: -Uninstall" -IncludeCollectionName " | E30: "
A32: Exclude All Hosts from Install | C32: Remove-CMDeviceCollectionIncludeMembershipRule -CollectionName " | D32: -install" -IncludeCollectionName " | E32: " -force
A33: Exclude All Hosts from UInstall | C33: Remove-CMDeviceCollectionIncludeMembershipRule -CollectionName " | D33: -Uninstall" -IncludeCollectionName " | E33: " -force
